Workbook

Sheet Sheet4
A1: 藥品代碼 | B1: 藥名 | C1: 12/27盤點量 | D1: 12/27-12/29 | E1: 12/30預期量 | F1: 備註 | G1: 12/30電腦量 | H1: 12月/30上藥量 | I1: 7day
A2: ABI02O | B2: Abilify 5mg Tab# | C2: 1184 | D2: =IFERROR(VLOOKUP(A2,'1227-29耗量'!$A$1:$C$602,3,FALSE),0) -> 5 | E2: =C2-D2 -> 1179 | F2: =IFERROR(IF(E2=G2,"OK","錯誤"),"無資料") -> 無資料 | G2: =VLOOKUP(A2,Sheet5!$A$2:$D$415,4,FALSE) -> #N/A | H2: =VLOOKUP(A2,Sheet5!$A$2:$D$415,3,FALSE) -> #N/A | I2: =VLOOKUP(A2,'1201-29周均耗用'!$A$1:$C$602,3,FALSE) -> 114
A3: ABI03O | B3: ABILIFY 15mg Tab# | C3: 760 | D3: =IFERROR(VLOOKUP(A3,'1227-29耗量'!$A$1:$C$602,3,FALSE),0) -> 3 | E3: =C3-D3 -> 757 | F3: =IFERROR(IF(E3=G3,"OK","錯誤"),"無資料") -> 無資料 | G3: =VLOOKUP(A3,Sheet5!$A$2:$D$415,4,FALSE) -> #N/A | H3: =VLOOKUP(A3,Sheet5!$A$2:$D$415,3,FALSE) -> #N/A | I3: =VLOOKUP(A3,'1201-29周均耗用'!$A$1:$C$602,3,FALSE) -> 91.8
A4: ABI04I | B4: Abilify maintena 400mg Syringe | C4: 12 | D4: =IFERROR(VLOOKUP(A4,'1227-29耗量'!$A$1:$C$602,3,FALSE),0) -> 0 | E4: =C4-D4 -> 12 | F4: =IFERROR(IF(E4=G4,"OK","錯誤"),"無資料") -> 錯誤 | G4: =VLOOKUP(A4,Sheet5!$A$2:$D$415,4,FALSE) -> 7 | H4: =VLOOKUP(A4,Sheet5!$A$2:$D$415,3,FALSE) -> 12 | I4: =VLOOKUP(A4,'1201-29周均耗用'!$A$1:$C$602,3,FALSE) -> 3.5
A5: ABI04O | B5: Abiratred FC 250mg Tab | C5: 0 | D5: =IFERROR(VLOOKUP(A5,'1227-29耗量'!$A$1:$C$602,3,FALSE),0) -> 0 | E5: =C5-D5 -> 0 | F5: =IFERROR(IF(E5=G5,"OK","錯誤"),"無資料") -> 無資料 | G5: =VLOOKUP(A5,Sheet5!$A$2:$D$415,4,FALSE) -> #N/A | H5: =VLOOKUP(A5,Sheet5!$A$2:$D$415,3,FALSE) -> #N/A | I5: =VLOOKUP(A5,'1201-29周均耗用'!$A$1:$C$602,3,FALSE) -> #N/A
A6: ACA01O | B6: Acarose 50mg Tab# | C6: 844 | D6: =IFERROR(VLOOKUP(A6,'1227-29耗量'!$A$1:$C$602,3,FALSE),0) -> 31 | E6: =C6-D6 -> 813 | F6: =IFERROR(IF(E6=G6,"OK","錯誤"),"無資料") -> 無資料 | G6: =VLOOKUP(A6,Sheet5!$A$2:$D$415,4,FALSE) -> #N/A | H6: =VLOOKUP(A6,Sheet5!$A$2:$D$415,3,FALSE) -> #N/A | I6: =VLOOKUP(A6,'1201-29周均耗用'!$A$1:$C$602,3,FALSE) -> 230.2
A7: ACA02O | B7: A-Cal 500mg Tab | C7: 1383 | D7: =IFERROR(VLOOKUP(A7,'1227-29耗量'!$A$1:$C$602,3,FALSE),0) -> 61 | E7: =C7-D7 -> 1322 | F7: =IFERROR(IF(E7=G7,"OK","錯誤"),"無資料") -> 無資料 | G7: =VLOOKUP(A7,Sheet5!$A$2:$D$415,4,FALSE) -> #N/A | H7: =VLOOKUP(A7,Sheet5!$A$2:$D$415,3,FALSE) -> #N/A | I7: =VLOOKUP(A7,'1201-29周均耗用'!$A$1:$C$602,3,FALSE) -> 280
A8: ACD01I | B8: ACD Solution-C Bot | C8: 0 | D8: =IFERROR(VLOOKUP(A8,'1227-29耗量'!$A$1:$C$602,3,FALSE),0) -> 0 | E8: =C8-D8 -> 0 | F8: =IFERROR(IF(E8=G8,"OK","錯誤"),"無資料") -> 無資料 | G8: =VLOOKUP(A8,Sheet5!$A$2:$D$415,4,FALSE) -> #N/A | H8: =VLOOKUP(A8,Sheet5!$A$2:$D$415,3,FALSE) -> #N/A | I8: =VLOOKUP(A8,'1201-29周均耗用'!$A$1:$C$602,3,FALSE) -> #N/A
A9: ACE01I | B9: Acemycin 500mg/2ml Vial# | C9: 14 | D9: =VLOOKUP(A9,'1227-29耗量'!$A$1:$C$602,3,FALSE) -> 2 | E9: =C9-D9 -> 12 | F9: =IFERROR(IF(E9=G9,"OK","錯誤"),"無資料") -> 錯誤 | G9: =VLOOKUP(A9,Sheet5!$A$2:$D$415,4,FALSE) -> 16 | H9: =VLOOKUP(A9,Sheet5!$A$2:$D$415,3,FALSE) -> 20 | I9: =VLOOKUP(A9,'1201-29周均耗用'!$A$1:$C$602,3,FALSE) -> 2.8
A10: ACE02I | B10: Acetamol 1gm Vial | C10: 122 | D10: =IFERROR(VLOOKUP(A10,'1227-29耗量'!$A$1:$C$602,3,FALSE),0) -> 9 | E10: =C10-D10 -> 113 | F10: =IFERROR(IF(E10=G10,"OK","錯誤"),"無資料") -> 無資料 | G10: =VLOOKUP(A10,Sheet5!$A$2:$D$415,4,FALSE) -> #N/A | H10: =VLOOKUP(A10,Sheet5!$A$2:$D$415,3,FALSE) -> #N/A | I10: =VLOOKUP(A10,'1201-29周均耗用'!$A$1:$C$602,3,FALSE) -> 17.5
A11: ACE04O | B11: Acemet 60mg Cap | C11: 1374 | D11: =VLOOKUP(A11,'1227-29耗量'!$A$1:$C$602,3,FALSE) -> 32 | E11: =C11-D11 -> 1342 | F11: =IFERROR(IF(E11=G11,"OK","錯誤"),"無資料") -> 錯誤 | G11: =VLOOKUP(A11,Sheet5!$A$2:$D$415,4,FALSE) -> 260 | H11: =VLOOKUP(A11,Sheet5!$A$2:$D$415,3,FALSE) -> 1000 | I11: =VLOOKUP(A11,'1201-29周均耗用'!$A$1:$C$602,3,FALSE) -> 124.8
A12: ACE05O | B12: Acetazolamide 250mg Tab | C12: 244 | D12: =IFERROR(VLOOKUP(A12,'1227-29耗量'!$A$1:$C$602,3,FALSE),0) -> 1 | E12: =C12-D12 -> 243 | F12: =IFERROR(IF(E12=G12,"OK","錯誤"),"無資料") -> 無資料 | G12: =VLOOKUP(A12,Sheet5!$A$2:$D$415,4,FALSE) -> #N/A | H12: =VLOOKUP(A12,Sheet5!$A$2:$D$415,3,FALSE) -> #N/A | I12: =VLOOKUP(A12,'1201-29周均耗用'!$A$1:$C$602,3,FALSE) -> 7.2
A13: ACL01E | B13: Aclovir Cream 5% 5gm | C13: 16 | D13: =IFERROR(VLOOKUP(A13,'1227-29耗量'!$A$1:$C$602,3,FALSE),0) -> 1 | E13: =C13-D13 -> 15 | F13: =IFERROR(IF(E13=G13,"OK","錯誤"),"無資料") -> 無資料 | G13: =VLOOKUP(A13,Sheet5!$A$2:$D$415,4,FALSE) -> #N/A | H13: =VLOOKUP(A13,Sheet5!$A$2:$D$415,3,FALSE) -> #N/A | I13: =VLOOKUP(A13,'1201-29周均耗用'!$A$1:$C$602,3,FALSE) -> #N/A
A14: ACL01I | B14: Aclasta 5mg/100ml Vial# | C14: 0 | D14: =IFERROR(VLOOKUP(A14,'1227-29耗量'!$A$1:$C$602,3,FALSE),0) -> 0 | E14: =C14-D14 -> 0 | F14: =IFERROR(IF(E14=G14,"OK","錯誤"),"無資料") -> 無資料 | G14: =VLOOKUP(A14,Sheet5!$A$2:$D$415,4,FALSE) -> #N/A | H14: =VLOOKUP(A14,Sheet5!$A$2:$D$415,3,FALSE) -> #N/A | I14: =VLOOKUP(A14,'1201-29周均耗用'!$A$1:$C$602,3,FALSE) -> #N/A
A15: ACT01I | B15: Actemra 200mg/10ml vial# | C15: 15 | D15: =IFERROR(VLOOKUP(A15,'1227-29耗量'!$A$1:$C$602,3,FALSE),0) -> 0 | E15: =C15-D15 -> 15 | F15: =IFERROR(IF(E15=G15,"OK","錯誤"),"無資料") -> 錯誤 | G15: =VLOOKUP(A15,Sheet5!$A$2:$D$415,4,FALSE) -> 10 | H15: =VLOOKUP(A15,Sheet5!$A$2:$D$415,3,FALSE) -> 10 | I15: =VLOOKUP(A15,'1201-29周均耗用'!$A$1:$C$602,3,FALSE) -> 4
A16: ACT01O | B16: Actos 30mg Tab# | C16: 79 | D16: =VLOOKUP(A16,'1227-29耗量'!$A$1:$C$602,3,FALSE) -> 4 | E16: =C16-D16 -> 75 | F16: =IFERROR(IF(E16=G16,"OK","錯誤"),"無資料") -> 錯誤 | G16: =VLOOKUP(A16,Sheet5!$A$2:$D$415,4,FALSE) -> 56 | H16: =VLOOKUP(A16,Sheet5!$A$2:$D$415,3,FALSE) -> 90 | I16: =VLOOKUP(A16,'1201-29周均耗用'!$A$1:$C$602,3,FALSE) -> 39
A17: ACT02I | B17: Actilyse 50mg/50ml Vial# | C17: 0 | D17: =IFERROR(VLOOKUP(A17,'1227-29耗量'!$A$1:$C$602,3,FALSE),0) -> 0 | E17: =C17-D17 -> 0 | F17: =IFERROR(IF(E17=G17,"OK","錯誤"),"無資料") -> 無資料 | G17: =VLOOKUP(A17,Sheet5!$A$2:$D$415,4,FALSE) -> #N/A | H17: =VLOOKUP(A17,Sheet5!$A$2:$D$415,3,FALSE) -> #N/A | I17: =VLOOKUP(A17,'1201-29周均耗用'!$A$1:$C$602,3,FALSE) -> #N/A
A18: ACT02O | B18: ACTEIN Effervescent 600mg Tab | C18: 743 | D18: =VLOOKUP(A18,'1227-29耗量'!$A$1:$C$602,3,FALSE) -> 118 | E18: =C18-D18 -> 625 | F18: =IFERROR(IF(E18=G18,"OK","錯誤"),"無資料") -> 錯誤 | G18: =VLOOKUP(A18,Sheet5!$A$2:$D$415,4,FALSE) -> 624 | H18: =VLOOKUP(A18,Sheet5!$A$2:$D$415,3,FALSE) -> 1120 | I18: =VLOOKUP(A18,'1201-29周均耗用'!$A$1:$C$602,3,FALSE) -> 535.8
A19: ACT03I | B19: Actrapid HM(RI) 1000iu/10ml Vial | C19: 6 | D19: =IFERROR(VLOOKUP(A19,'1227-29耗量'!$A$1:$C$602,3,FALSE),0) -> 0 | E19: =C19-D19 -> 6 | F19: =IFERROR(IF(E19=G19,"OK","錯誤"),"無資料") -> 無資料 | G19: =VLOOKUP(A19,Sheet5!$A$2:$D$415,4,FALSE) -> #N/A | H19: =VLOOKUP(A19,Sheet5!$A$2:$D$415,3,FALSE) -> #N/A | I19: =VLOOKUP(A19,'1201-29周均耗用'!$A$1:$C$602,3,FALSE) -> -1.5
A20: ACT06O | B20: Actein Granules 200mg/3gm Pack | C20: 9250 | D20: =VLOOKUP(A20,'1227-29耗量'!$A$1:$C$602,3,FALSE) -> 565 | E20: =C20-D20 -> 8685 | F20: =IFERROR(IF(E20=G20,"OK","錯誤"),"無資料") -> 錯誤 | G20: =VLOOKUP(A20,Sheet5!$A$2:$D$415,4,FALSE) -> 4081 | H20: =VLOOKUP(A20,Sheet5!$A$2:$D$415,3,FALSE) -> 11200 | I20: =VLOOKUP(A20,'1201-29周均耗用'!$A$1:$C$602,3,FALSE) -> 3445.2
A21: ACT07I | B21: Actemra 80mg/4ml vial# | C21: 10 | D21: =IFERROR(VLOOKUP(A21,'1227-29耗量'!$A$1:$C$602,3,FALSE),0) -> 0 | E21: =C21-D21 -> 10 | F21: =IFERROR(IF(E21=G21,"OK","錯誤"),"無資料") -> 錯誤 | G21: =VLOOKUP(A21,Sheet5!$A$2:$D$415,4,FALSE) -> 6 | H21: =VLOOKUP(A21,Sheet5!$A$2:$D$415,3,FALSE) -> 10 | I21: =VLOOKUP(A21,'1201-29周均耗用'!$A$1:$C$602,3,FALSE) -> 2
A22: ACT08I | B22: ACTEMRA 162mg/0.9ml Pen# | C22: 0 | D22: =IFERROR(VLOOKUP(A22,'1227-29耗量'!$A$1:$C$602,3,FALSE),0) -> 0 | E22: =C22-D22 -> 0 | F22: =IFERROR(IF(E22=G22,"OK","錯誤"),"無資料") -> 無資料 | G22: =VLOOKUP(A22,Sheet5!$A$2:$D$415,4,FALSE) -> #N/A | H22: =VLOOKUP(A22,Sheet5!$A$2:$D$415,3,FALSE) -> #N/A | I22: =VLOOKUP(A22,'1201-29周均耗用'!$A$1:$C$602,3,FALSE) -> #N/A
A23: ACY02O | B23: Acylo 400mg Tab | C23: 520 | D23: =VLOOKUP(A23,'1227-29耗量'!$A$1:$C$602,3,FALSE) -> 10 | E23: =C23-D23 -> 510 | F23: =IFERROR(IF(E23=G23,"OK","錯誤"),"無資料") -> 錯誤 | G23: =VLOOKUP(A23,Sheet5!$A$2:$D$415,4,FALSE) -> 133 | H23: =VLOOKUP(A23,Sheet5!$A$2:$D$415,3,FALSE) -> 300 | I23: =VLOOKUP(A23,'1201-29周均耗用'!$A$1:$C$602,3,FALSE) -> 81.2
A24: ACZ01E | B24: Aczo Gel 5% 10gm Tube | C24: 0 | D24: =IFERROR(VLOOKUP(A24,'1227-29耗量'!$A$1:$C$602,3,FALSE),0) -> 0 | E24: =C24-D24 -> 0 | F24: =IFERROR(IF(E24=G24,"OK","錯誤"),"無資料") -> 無資料 | G24: =VLOOKUP(A24,Sheet5!$A$2:$D$415,4,FALSE) -> #N/A | H24: =VLOOKUP(A24,Sheet5!$A$2:$D$415,3,FALSE) -> #N/A | I24: =VLOOKUP(A24,'1201-29周均耗用'!$A$1:$C$602,3,FALSE) -> #N/A
A25: ADE01I | B25: Adenocor 6mg/2ml Vial | C25: 319 | D25: =IFERROR(VLOOKUP(A25,'1227-29耗量'!$A$1:$C$602,3,FALSE),0) -> 1 | E25: =C25-D25 -> 318 | F25: =IFERROR(IF(E25=G25,"OK","錯誤"),"無資料") -> 無資料 | G25: =VLOOKUP(A25,Sheet5!$A$2:$D$415,4,FALSE) -> #N/A | H25: =VLOOKUP(A25,Sheet5!$A$2:$D$415,3,FALSE) -> #N/A | I25: =VLOOKUP(A25,'1201-29周均耗用'!$A$1:$C$602,3,FALSE) -> -2.8
A26: ADE01O | B26: Adempas FC 2mg Tab# | C26: 0 | D26: =IFERROR(VLOOKUP(A26,'1227-29耗量'!$A$1:$C$602,3,FALSE),0) -> 0 | E26: =C26-D26 -> 0 | F26: =IFERROR(IF(E26=G26,"OK","錯誤"),"無資料") -> 無資料 | G26: =VLOOKUP(A26,Sheet5!$A$2:$D$415,4,FALSE) -> #N/A | H26: =VLOOKUP(A26,Sheet5!$A$2:$D$415,3,FALSE) -> #N/A | I26: =VLOOKUP(A26,'1201-29周均耗用'!$A$1:$C$602,3,FALSE) -> #N/A
A27: ADE02O | B27: ADEMPAS FC 2.5mg Tab# | C27: 27 | D27: =IFERROR(VLOOKUP(A27,'1227-29耗量'!$A$1:$C$602,3,FALSE),0) -> 0 | E27: =C27-D27 -> 27 | F27: =IFERROR(IF(E27=G27,"OK","錯誤"),"無資料") -> 無資料 | G27: =VLOOKUP(A27,Sheet5!$A$2:$D$415,4,FALSE) -> #N/A | H27: =VLOOKUP(A27,Sheet5!$A$2:$D$415,3,FALSE) -> #N/A | I27: =VLOOKUP(A27,'1201-29周均耗用'!$A$1:$C$602,3,FALSE) -> #N/A
A28: ADI08I | B28: AdimFlu-S (公費) 0.5mL Syringe | C28: 0 | D28: =IFERROR(VLOOKUP(A28,'1227-29耗量'!$A$1:$C$602,3,FALSE),0) -> 0 | E28: =C28-D28 -> 0 | F28: =IFERROR(IF(E28=G28,"OK","錯誤"),"無資料") -> 無資料 | G28: =VLOOKUP(A28,Sheet5!$A$2:$D$415,4,FALSE) -> #N/A | H28: =VLOOKUP(A28,Sheet5!$A$2:$D$415,3,FALSE) -> #N/A | I28: =VLOOKUP(A28,'1201-29周均耗用'!$A$1:$C$602,3,FALSE) -> 0.2
A29: ADR02I | B29: Adrenalin 1mg/1ml Amp | C29: 109 | D29: =IFERROR(VLOOKUP(A29,'1227-29耗量'!$A$1:$C$602,3,FALSE),0) -> 24 | E29: =C29-D29 -> 85 | F29: =IFERROR(IF(E29=G29,"OK","錯誤"),"無資料") -> 無資料 | G29: =VLOOKUP(A29,Sheet5!$A$2:$D$415,4,FALSE) -> #N/A | H29: =VLOOKUP(A29,Sheet5!$A$2:$D$415,3,FALSE) -> #N/A | I29: =VLOOKUP(A29,'1201-29周均耗用'!$A$1:$C$602,3,FALSE) -> 86
A30: ADV01O | B30: Advagraf PR 0.5mg Cap | C30: 70 | D30: =IFERROR(VLOOKUP(A30,'1227-29耗量'!$A$1:$C$602,3,FALSE),0) -> 0 | E30: =C30-D30 -> 70 | F30: =IFERROR(IF(E30=G30,"OK","錯誤"),"無資料") -> 錯誤 | G30: =VLOOKUP(A30,Sheet5!$A$2:$D$415,4,FALSE) -> -3 | H30: =VLOOKUP(A30,Sheet5!$A$2:$D$415,3,FALSE) -> 50 | I30: =VLOOKUP(A30,'1201-29周均耗用'!$A$1:$C$602,3,FALSE) -> 9
A31: ADV02O | B31: ADVAGRAF PR 1mg Cap | C31: 36 | D31: =VLOOKUP(A31,'1227-29耗量'!$A$1:$C$602,3,FALSE) -> 3 | E31: =C31-D31 -> 33 | F31: =IFERROR(IF(E31=G31,"OK","錯誤"),"無資料") -> 錯誤 | G31: =VLOOKUP(A31,Sheet5!$A$2:$D$415,4,FALSE) -> -1 | H31: =VLOOKUP(A31,Sheet5!$A$2:$D$415,3,FALSE) -> 50 | I31: =VLOOKUP(A31,'1201-29周均耗用'!$A$1:$C$602,3,FALSE) -> 19.5
A32: ADV03O | B32: ADVAGRAF PR 5mg Cap | C32: 0 | D32: =IFERROR(VLOOKUP(A32,'1227-29耗量'!$A$1:$C$602,3,FALSE),0) -> 0 | E32: =C32-D32 -> 0 | F32: =IFERROR(IF(E32=G32,"OK","錯誤"),"無資料") -> 無資料 | G32: =VLOOKUP(A32,Sheet5!$A$2:$D$415,4,FALSE) -> #N/A | H32: =VLOOKUP(A32,Sheet5!$A$2:$D$415,3,FALSE) -> #N/A | I32: =VLOOKUP(A32,'1201-29周均耗用'!$A$1:$C$602,3,FALSE) -> 3.2
A33: AET02I | B33: Aethoxysklerol 20mg/2ml amp | C33: 0 | D33: =IFERROR(VLOOKUP(A33,'1227-29耗量'!$A$1:$C$602,3,FALSE),0) -> 0 | E33: =C33-D33 -> 0 | F33: =IFERROR(IF(E33=G33,"OK","錯誤"),"無資料") -> 無資料 | G33: =VLOOKUP(A33,Sheet5!$A$2:$D$415,4,FALSE) -> #N/A | H33: =VLOOKUP(A33,Sheet5!$A$2:$D$415,3,FALSE) -> #N/A | I33: =VLOOKUP(A33,'1201-29周均耗用'!$A$1:$C$602,3,FALSE) -> #N/A
A34: AFI01O | B34: Afinitor 5mg Tab# | C34: 13 | D34: =IFERROR(VLOOKUP(A34,'1227-29耗量'!$A$1:$C$602,3,FALSE),0) -> 0 | E34: =C34-D34 -> 13 | F34: =IFERROR(IF(E34=G34,"OK","錯誤"),"無資料") -> 無資料 | G34: =VLOOKUP(A34,Sheet5!$A$2:$D$415,4,FALSE) -> #N/A | H34: =VLOOKUP(A34,Sheet5!$A$2:$D$415,3,FALSE) -> #N/A | I34: =VLOOKUP(A34,'1201-29周均耗用'!$A$1:$C$602,3,FALSE) -> 2
A35: AGG01I | B35: Aggrastat 12.5mg/50ml Vial# | C35: 4 | D35: =IFERROR(VLOOKUP(A35,'1227-29耗量'!$A$1:$C$602,3,FALSE),0) -> 0 | E35: =C35-D35 -> 4 | F35: =IFERROR(IF(E35=G35,"OK","錯誤"),"無資料") -> 無資料 | G35: =VLOOKUP(A35,Sheet5!$A$2:$D$415,4,FALSE) -> #N/A | H35: =VLOOKUP(A35,Sheet5!$A$2:$D$415,3,FALSE) -> #N/A | I35: =VLOOKUP(A35,'1201-29周均耗用'!$A$1:$C$602,3,FALSE) -> 0.2
A36: AGG02I | B36: Agglutex 25000iu/5ml Vial | C36: 125 | D36: =IFERROR(VLOOKUP(A36,'1227-29耗量'!$A$1:$C$602,3,FALSE),0) -> 1 | E36: =C36-D36 -> 124 | F36: =IFERROR(IF(E36=G36,"OK","錯誤"),"無資料") -> 無資料 | G36: =VLOOKUP(A36,Sheet5!$A$2:$D$415,4,FALSE) -> #N/A | H36: =VLOOKUP(A36,Sheet5!$A$2:$D$415,3,FALSE) -> #N/A | I36: =VLOOKUP(A36,'1201-29周均耗用'!$A$1:$C$602,3,FALSE) -> 3.5
A37: AGR01O | B37: Agrylin 0.5mg Cap# | C37: 96 | D37: =IFERROR(VLOOKUP(A37,'1227-29耗量'!$A$1:$C$602,3,FALSE),0) -> 0 | E37: =C37-D37 -> 96 | F37: =IFERROR(IF(E37=G37,"OK","錯誤"),"無資料") -> 無資料 | G37: =VLOOKUP(A37,Sheet5!$A$2:$D$415,4,FALSE) -> #N/A | H37: =VLOOKUP(A37,Sheet5!$A$2:$D$415,3,FALSE) -> #N/A | I37: =VLOOKUP(A37,'1201-29周均耗用'!$A$1:$C$602,3,FALSE) -> #N/A
A38: AJO01I | B38: Ajovy 225mg/1.5ml Pen | C38: 3 | D38: =IFERROR(VLOOKUP(A38,'1227-29耗量'!$A$1:$C$602,3,FALSE),0) -> 0 | E38: =C38-D38 -> 3 | F38: =IFERROR(IF(E38=G38,"OK","錯誤"),"無資料") -> 無資料 | G38: =VLOOKUP(A38,Sheet5!$A$2:$D$415,4,FALSE) -> #N/A | H38: =VLOOKUP(A38,Sheet5!$A$2:$D$415,3,FALSE) -> #N/A | I38: =VLOOKUP(A38,'1201-29周均耗用'!$A$1:$C$602,3,FALSE) -> #N/A
A39: AKU01O | B39: AKuriT-3 275/75/150 Tab# | C39: 0 | D39: =IFERROR(VLOOKUP(A39,'1227-29耗量'!$A$1:$C$602,3,FALSE),0) -> 0 | E39: =C39-D39 -> 0 | F39: =IFERROR(IF(E39=G39,"OK","錯誤"),"無資料") -> 無資料 | G39: =VLOOKUP(A39,Sheet5!$A$2:$D$415,4,FALSE) -> #N/A | H39: =VLOOKUP(A39,Sheet5!$A$2:$D$415,3,FALSE) -> #N/A | I39: =VLOOKUP(A39,'1201-29周均耗用'!$A$1:$C$602,3,FALSE) -> #N/A
A40: AKU02O | B40: AKuriT-4 275/75/400/150 Tab# | C40: 97 | D40: =IFERROR(VLOOKUP(A40,'1227-29耗量'!$A$1:$C$602,3,FALSE),0) -> 12 | E40: =C40-D40 -> 85 | F40: =IFERROR(IF(E40=G40,"OK","錯誤"),"無資料") -> 無資料 | G40: =VLOOKUP(A40,Sheet5!$A$2:$D$415,4,FALSE) -> #N/A | H40: =VLOOKUP(A40,Sheet5!$A$2:$D$415,3,FALSE) -> #N/A | I40: =VLOOKUP(A40,'1201-29周均耗用'!$A$1:$C$602,3,FALSE) -> 26
...

Sheet Sheet5
A1: 藥品代碼 | B1: 藥品名稱 | C1: 實發量 | D1: 庫存量
A2: ABI04I | B2: Abilify maintena 400mg Syringe | C2: 12 | D2: 7
A3: ACE01I | B3: Acemycin 500mg/2ml Vial# | C3: 20 | D3: 16
A4: ACT01I | B4: Actemra 200mg/10ml vial# | C4: 10 | D4: 10
A5: ACT07I | B5: Actemra 80mg/4ml vial# | C5: 10 | D5: 6
A6: ALO01I | B6: Aloxi 0.25mg/5ml Vial# | C6: 90 | D6: 30
A7: AMI12I | B7: Aminopoly-H 500ml Bot | C7: 120 | D7: 39
A8: AMP02I | B8: Ampholipad 50mg Vial | C8: 250 | D8: -26
A9: AMP03I | B9: Ampolin 500mg Vial | C9: 500 | D9: 548
A10: ANE03I | B10: Anexate 0.5mg/5ml Amp# | C10: 80 | D10: 8
A11: ANG02I | B11: Angidil 10mg/10ml Amp | C11: 240 | D11: 115
A12: ANT01I | B12: Antifect 1g Vial# | C12: 2340 | D12: 609
A13: ASI01I | B13: Asiphylline 250mg/10ml Amp | C13: 150 | D13: 98
... A415: SCR01S | B415: Scrat Suspension 10ml Pack | C415: 600 | D415: 188

Sheet 1227-29耗量
A1: 藥品代碼 | B1: 商品名稱 | C1: 消耗量
A2: ACE01I | B2: Acemycin 500mg/2ml Vial# | C2: 2
A3: ACE02I | B3: Acetamol 1gm Vial | C3: 9
A4: ADD01I | B4: Addaven 10ml amp | C4: -1
A5: ADE01I | B5: Adenocor 6mg/2ml Vial | C5: 1
A6: ADR02I | B6: Adrenalin 1mg/1ml Amp | C6: 24
A7: AGG02I | B7: Agglutex 25000iu/5ml Vial | C7: 1
A8: ALO01I | B8: Aloxi 0.25mg/5ml Vial# | C8: 5
A9: AMI12I | B9: Aminopoly-H 500ml Bot | C9: 1
A10: AMO01I | B10: AmoClav 1.2g Vial | C10: 3
A11: AMP02I | B11: Ampholipad 50mg Vial | C11: 18
A12: AMP03I | B12: Ampolin 500mg Vial | C12: 0
A13: ANE03I | B13: Anexate 0.5mg/5ml Amp# | C13: 1
... A602: SER01S | B602: Seridol Oral Soln 30mg/30ml | C602: 4

Sheet 1201-29周均耗用
A1: 藥品代碼 | B1: 商品名稱 | C1: 周均消耗量
A2: 5FU01I | B2: 5-Fu 1g/20ml Vial (Fluorouracil) | C2: -0.2
A3: ABI04I | B3: Abilify maintena 400mg Syringe | C3: 3.5
A4: ACE01I | B4: Acemycin 500mg/2ml Vial# | C4: 2.8
A5: ACE02I | B5: Acetamol 1gm Vial | C5: 17.5
A6: ACT01I | B6: Actemra 200mg/10ml vial# | C6: 4
A7: ACT07I | B7: Actemra 80mg/4ml vial# | C7: 2
A8: ACT03I | B8: Actrapid HM(RI) 1000iu/10ml Vial | C8: -1.5
A9: ADD01I | B9: Addaven 10ml amp | C9: 6.8
A10: ADE01I | B10: Adenocor 6mg/2ml Vial | C10: -2.8
A11: ADI08I | B11: AdimFlu-S (公費) 0.5mL Syringe | C11: 0.2
A12: ADR02I | B12: Adrenalin 1mg/1ml Amp | C12: 86
A13: AGG02I | B13: Agglutex 25000iu/5ml Vial | C13: 3.5
... A936: WEM01S | B936: Wempty Susp 60mg/60ml Bot | C936: 0
